Workbook

Sheet Dashboard
A1: Program 1

Sheet StudentData
A1: Student_ID | B1: Gender | C1: Age | D1: Address | E1: Mother_Education | F1: Father_Education | G1: Internet_Access | H1: School_Support | I1: Family_Support | J1: Extra_Curricular_Activities | K1: Wants_Higher_Education | L1: Study_Time | M1: Number_of_class_Failures | N1: Number_of_Absences | O1: Final_Grade | P1: Dropped_Out
A2: STU0001 | B2: M | C2: 19 | D2: Urban | E2: Primary | F2: Secondary | G2: yes | H2: yes | I2: no | J2: yes | K2: yes | L2: 2 | M2: 0 | N2: 2 | O2: 14 | P2: =FALSE() -> FALSE
A3: STU0002 | B3: F | C3: 21 | D3: Rural | E3: Secondary | F3: Primary | G3: no | H3: yes | I3: yes | J3: no | K3: yes | L3: 2 | M3: 0 | N3: 5 | O3: 17 | P3: =FALSE() -> FALSE
A4: STU0003 | B4: M | C4: 20 | D4: Rural | E4: Primary | F4: Primary | G4: yes | H4: yes | I4: no | J4: yes | K4: yes | L4: 3 | M4: 0 | N4: 3 | O4: 13 | P4: =FALSE() -> FALSE
A5: STU0004 | B5: M | C5: 16 | D5: Urban | E5: Secondary | F5: Primary | G5: yes | H5: yes | I5: no | J5: no | K5: no | L5: 2 | M5: 0 | N5: 8 | O5: 16 | P5: =FALSE() -> FALSE
A6: STU0005 | B6: F | C6: 21 | D6: Urban | E6: Secondary | F6: Primary | G6: no | H6: no | I6: no | J6: no | K6: yes | L6: 3 | M6: 0 | N6: 12 | O6: 12 | P6: =FALSE() -> FALSE
A7: STU0006 | B7: M | C7: 19 | D7: Urban | E7: Primary | F7: Secondary | G7: yes | H7: no | I7: no | J7: yes | K7: yes | L7: 4 | M7: 0 | N7: 6 | O7: 18 | P7: =FALSE() -> FALSE
A8: STU0007 | B8: M | C8: 17 | D8: Rural | E8: Secondary | F8: Higher | G8: yes | H8: yes | I8: yes | J8: no | K8: yes | L8: 2 | M8: 0 | N8: 9 | O8: 15 | P8: =FALSE() -> FALSE
A9: STU0008 | B9: M | C9: 19 | D9: Urban | E9: Higher | F9: Primary | G9: yes | H9: no | I9: yes | J9: no | K9: yes | L9: 2 | M9: 0 | N9: 0 | O9: 15 | P9: =FALSE() -> FALSE
A10: STU0009 | B10: F | C10: 22 | D10: Rural | F10: Secondary | G10: yes | H10: no | I10: no | J10: yes | K10: yes | L10: 3 | M10: 2 | N10: 18 | O10: 7 | P10: =TRUE() -> TRUE
A11: STU0010 | B11: F | C11: 21 | D11: Urban | E11: Secondary | F11: Secondary | G11: yes | H11: yes | I11: yes | J11: yes | K11: yes | L11: 2 | M11: 0 | N11: 7 | O11: 12 | P11: =FALSE() -> FALSE
A12: STU0011 | B12: F | C12: 21 | D12: Urban | E12: Higher | F12: Higher | G12: yes | H12: yes | I12: yes | J12: no | K12: yes | L12: 2 | M12: 3 | N12: 10 | O12: 6 | P12: =TRUE() -> TRUE
A13: STU0012 | B13: M | C13: 18 | D13: Urban | E13: Primary | F13: Secondary | G13: yes | H13: no | I13: yes | J13: no | K13: yes | L13: 2 | M13: 3 | N13: 8 | O13: 8 | P13: =TRUE() -> TRUE
A14: STU0013 | B14: M | C14: 21 | D14: Rural | F14: Primary | G14: yes | H14: no | I14: yes | J14: yes | K14: yes | L14: 2 | M14: 0 | N14: 7 | O14: 13 | P14: =FALSE() -> FALSE
A15: STU0014 | B15: M | C15: 18 | D15: Urban | E15: Primary | F15: Secondary | G15: yes | H15: yes | I15: yes | J15: yes | K15: yes | L15: 1 | M15: 1 | N15: 8 | O15: 9 | P15: =FALSE() -> FALSE
A16: STU0015 | B16: F | C16: 20 | D16: Urban | E16: Higher | F16: Primary | G16: yes | H16: no | I16: no | J16: no | K16: yes | L16: 2 | M16: 0 | N16: 11 | O16: 11 | P16: =FALSE() -> FALSE
A17: STU0016 | B17: F | C17: 20 | D17: Rural | F17: Higher | G17: yes | H17: no | I17: yes | J17: yes | K17: yes | L17: 1 | M17: 1 | N17: 12 | O17: 11 | P17: =FALSE() -> FALSE
A18: STU0017 | B18: M | C18: 16 | D18: Urban | E18: Primary | F18: Secondary | G18: yes | H18: no | I18: no | J18: no | K18: yes | L18: 2 | M18: 0 | N18: 7 | O18: 15 | P18: =FALSE() -> FALSE
A19: STU0018 | B19: F | C19: 17 | D19: Rural | F19: Secondary | G19: yes | H19: yes | I19: no | J19: yes | K19: yes | L19: 2 | M19: 0 | N19: 11 | O19: 11 | P19: =FALSE() -> FALSE
A20: STU0019 | B20: M | C20: 15 | D20: Urban | E20: Primary | G20: yes | H20: yes | I20: yes | J20: no | K20: yes | L20: 4 | M20: 0 | N20: 5 | O20: 15 | P20: =FALSE() -> FALSE
A21: STU0020 | B21: M | C21: 16 | D21: Urban | E21: Secondary | F21: Secondary | G21: yes | H21: no | I21: yes | J21: no | K21: no | L21: 1 | M21: 0 | N21: 5 | O21: 13 | P21: =FALSE() -> FALSE
A22: STU0021 | B22: M | C22: 18 | D22: Urban | E22: Primary | F22: Higher | G22: yes | H22: yes | I22: yes | J22: no | K22: yes | L22: 2 | M22: 3 | N22: 8 | O22: 9 | P22: =TRUE() -> TRUE
A23: STU0022 | B23: F | C23: 18 | D23: Urban | E23: Secondary | F23: Secondary | G23: no | H23: no | I23: no | J23: no | K23: yes | L23: 2 | M23: 0 | N23: 4 | O23: 15 | P23: =FALSE() -> FALSE
A24: STU0023 | B24: M | C24: 16 | D24: Urban | E24: Secondary | F24: Secondary | G24: yes | H24: no | I24: no | J24: no | K24: yes | L24: 1 | M24: 1 | N24: 11 | O24: 6 | P24: =TRUE() -> TRUE
A25: STU0024 | B25: M | C25: 18 | D25: Urban | E25: Higher | F25: Higher | G25: yes | H25: yes | I25: yes | J25: no | K25: yes | L25: 1 | M25: 3 | N25: 14 | O25: 4 | P25: =TRUE() -> TRUE
A26: STU0025 | B26: M | C26: 19 | D26: Urban | F26: Higher | G26: no | H26: no | I26: yes | J26: no | K26: yes | L26: 1 | M26: 0 | N26: 6 | O26: 10 | P26: =FALSE() -> FALSE
A27: STU0026 | B27: F | C27: 16 | D27: Urban | E27: Higher | F27: Primary | G27: yes | H27: no | I27: yes | J27: yes | K27: yes | L27: 1 | M27: 0 | N27: 5 | O27: 12 | P27: =FALSE() -> FALSE
A28: STU0027 | B28: F | C28: 17 | D28: Urban | E28: Secondary | F28: Secondary | G28: yes | H28: no | I28: yes | J28: no | K28: yes | L28: 1 | M28: 2 | N28: 8 | O28: 10 | P28: =TRUE() -> TRUE
A29: STU0028 | B29: F | C29: 17 | D29: Urban | E29: Primary | F29: Secondary | G29: no | H29: no | I29: no | J29: yes | K29: yes | L29: 2 | M29: 0 | N29: 5 | O29: 9 | P29: =FALSE() -> FALSE
A30: STU0029 | B30: F | C30: 19 | D30: Urban | E30: Higher | F30: Secondary | G30: yes | H30: no | I30: no | J30: no | K30: yes | L30: 2 | M30: 0 | N30: 4 | O30: 10 | P30: =FALSE() -> FALSE
A31: STU0030 | B31: M | C31: 17 | D31: Urban | E31: Higher | F31: Primary | G31: yes | H31: no | I31: yes | J31: no | K31: no | L31: 1 | M31: 0 | N31: 7 | O31: 10 | P31: =FALSE() -> FALSE
A32: STU0031 | B32: M | C32: 20 | D32: Urban | E32: Primary | F32: Primary | G32: yes | H32: no | I32: no | J32: yes | K32: yes | L32: 1 | M32: 2 | N32: 12 | O32: 6 | P32: =TRUE() -> TRUE
A33: STU0032 | B33: M | C33: 17 | D33: Urban | E33: Higher | F33: Higher | G33: yes | H33: no | I33: yes | J33: yes | K33: yes | L33: 1 | M33: 0 | N33: 4 | O33: 14 | P33: =FALSE() -> FALSE
A34: STU0033 | B34: F | C34: 18 | D34: Urban | E34: Secondary | F34: Higher | G34: yes | H34: no | I34: no | J34: yes | K34: yes | L34: 2 | M34: 0 | N34: 4 | O34: 14 | P34: =FALSE() -> FALSE
A35: STU0034 | B35: F | C35: 18 | D35: Urban | E35: Secondary | F35: Higher | G35: no | H35: yes | I35: yes | J35: no | K35: yes | L35: 2 | M35: 0 | N35: 5 | O35: 16 | P35: =FALSE() -> FALSE
A36: STU0035 | B36: F | C36: 16 | D36: Urban | E36: Higher | F36: Higher | G36: no | H36: yes | I36: yes | J36: yes | K36: yes | L36: 2 | M36: 0 | N36: 4 | O36: 10 | P36: =FALSE() -> FALSE
A37: STU0036 | B37: F | C37: 20 | D37: Urban | E37: Secondary | F37: Secondary | G37: yes | H37: yes | I37: no | J37: yes | K37: yes | L37: 1 | M37: 0 | N37: 3 | O37: 15 | P37: =FALSE() -> FALSE
A38: STU0037 | B38: F | C38: 16 | D38: Urban | E38: Higher | F38: Higher | G38: yes | H38: no | I38: yes | J38: no | K38: yes | L38: 1 | M38: 1 | N38: 6 | O38: 9 | P38: =FALSE() -> FALSE
A39: STU0038 | B39: F | C39: 17 | D39: Urban | E39: Secondary | F39: Higher | G39: yes | H39: no | I39: no | J39: no | K39: yes | L39: 4 | M39: 2 | N39: 20 | O39: 9 | P39: =TRUE() -> TRUE
A40: STU0039 | B40: F | C40: 21 | D40: Urban | E40: Higher | F40: Secondary | G40: no | H40: no | I40: no | J40: yes | K40: yes | L40: 1 | M40: 0 | N40: 12 | O40: 7 | P40: =FALSE() -> FALSE
...

Sheet Retention Overview
A1: Overall Student Dropout Rate
A3: Dropped_Out | B3: Count of Students | C3: % of Grand Total
A4: FALSE | B4: =COUNTIF(StudentData!$P$2:$P$301,A4) -> 244 | C4: =B4/$B$6 -> 0.81333333
A5: TRUE | B5: =COUNTIF(StudentData!$P$2:$P$301,A5) -> 56 | C5: =B5/$B$6 -> 0.18666667
A6: Grand Total | B6: =SUM(B4:B5) -> 300 | C6: =B6/B6 -> 1

Sheet Grades Distribution
A1: Final Grade Distribution
A3: Final_Grade | B3: Number of Students
A4: 0 | B4: =COUNTIF(StudentData!$O$2:$O$301,A4) -> 0
A5: 1 | B5: =COUNTIF(StudentData!$O$2:$O$301,A5) -> 2
A6: 2 | B6: =COUNTIF(StudentData!$O$2:$O$301,A6) -> 0
A7: 3 | B7: =COUNTIF(StudentData!$O$2:$O$301,A7) -> 2
A8: 4 | B8: =COUNTIF(StudentData!$O$2:$O$301,A8) -> 4
A9: 5 | B9: =COUNTIF(StudentData!$O$2:$O$301,A9) -> 3
A10: 6 | B10: =COUNTIF(StudentData!$O$2:$O$301,A10) -> 9
A11: 7 | B11: =COUNTIF(StudentData!$O$2:$O$301,A11) -> 11
A12: 8 | B12: =COUNTIF(StudentData!$O$2:$O$301,A12) -> 7
A13: 9 | B13: =COUNTIF(StudentData!$O$2:$O$301,A13) -> 25
A14: 10 | B14: =COUNTIF(StudentData!$O$2:$O$301,A14) -> 27
A15: 11 | B15: =COUNTIF(StudentData!$O$2:$O$301,A15) -> 31
... A24: 20 | B24: =COUNTIF(StudentData!$O$2:$O$301,A24) -> 0

Sheet Grades Distribution 1
A1: Row Labels | B1: Sum of Number of Students
A2: 0 | B2: 0
A3: 1 | B3: 2
A4: 2 | B4: 0
A5: 3 | B5: 2
A6: 4 | B6: 4
A7: 5 | B7: 3
A8: 6 | B8: 9
A9: 7 | B9: 11
A10: 8 | B10: 7
A11: 9 | B11: 25
A12: 10 | B12: 27
A13: 11 | B13: 31
... A22: 20 | B22: 0
A23: Grand Total | B23: 300

Sheet Failures_Impact
A1: Dropout Status by Class Failures
A3: Number_of_class_Failures | B3: FALSE | C3: TRUE
A4: 0 | B4: =COUNTIFS(StudentData!$M$2:$M$301,A4,StudentData!$P$2:$P$301,"FALSE") -> 208 | C4: =COUNTIFS(StudentData!$M$2:$M$301,A4,StudentData!$P$2:$P$301,"TRUE") -> 7
A5: 1 | B5: =COUNTIFS(StudentData!$M$2:$M$301,A5,StudentData!$P$2:$P$301,"FALSE") -> 30 | C5: =COUNTIFS(StudentData!$M$2:$M$301,A5,StudentData!$P$2:$P$301,"TRUE") -> 14
A6: 2 | B6: =COUNTIFS(StudentData!$M$2:$M$301,A6,StudentData!$P$2:$P$301,"FALSE") -> 5 | C6: =COUNTIFS(StudentData!$M$2:$M$301,A6,StudentData!$P$2:$P$301,"TRUE") -> 23
A7: 3 | B7: =COUNTIFS(StudentData!$M$2:$M$301,A7,StudentData!$P$2:$P$301,"FALSE") -> 1 | C7: =COUNTIFS(StudentData!$M$2:$M$301,A7,StudentData!$P$2:$P$301,"TRUE") -> 12

Sheet Study Time Impact
A1: Average Final Grade by Study Time
A3: Study_Time | B3: Average of Final_Grade
A4: 1 (<2 hrs) | B4: =ROUND(AVERAGEIFS(StudentData!$O$2:$O$301,StudentData!$L$2:$L$301,1),0) -> 11
A5: 2 (2-5 hrs) | B5: =ROUND(AVERAGEIFS(StudentData!$O$2:$O$301,StudentData!$L$2:$L$301,2),0) -> 12
A6: 3 (5-10 hrs) | B6: =ROUND(AVERAGEIFS(StudentData!$O$2:$O$301,StudentData!$L$2:$L$301,3),0) -> 13
A7: 4 (>10 hrs) | B7: =ROUND(AVERAGEIFS(StudentData!$O$2:$O$301,StudentData!$L$2:$L$301,4),0) -> 13

Sheet Support Effect
A1: Average Final Grade by School & Family Support
A3: Family_Support | B3: School_Support: no | C3: School_Support: yes
A4: no | B4: =ROUND(AVERAGEIFS(StudentData!$O$2:$O$301,StudentData!$I$2:$I$301,A4,StudentData!$H$2:$H$301,"no"),1) -> 11 | C4: =ROUND(AVERAGEIFS(StudentData!$O$2:$O$301,StudentData!$I$2:$I$301,A4,StudentData!$H$2:$H$301,"yes"),1) -> 12.3
A5: yes | B5: =ROUND(AVERAGEIFS(StudentData!$O$2:$O$301,StudentData!$I$2:$I$301,A5,StudentData!$H$2:$H$301,"no"),1) -> 11.9 | C5: =ROUND(AVERAGEIFS(StudentData!$O$2:$O$301,StudentData!$I$2:$I$301,A5,StudentData!$H$2:$H$301,"yes"),1) -> 12.6

Sheet Absences Impact
A1: Average Final Grade by Number of Absences
A3: Absence_Bucket | B3: Average of Final_Grade
A4: 0-3 | B4: =IFERROR(ROUND(AVERAGEIFS(StudentData!$O$2:$O$301,StudentData!$N$2:$N$301,">="&0,StudentData!$N$2:$N$301,"<="&3),1),0) -> 13.9
A5: 4-7 | B5: =IFERROR(ROUND(AVERAGEIFS(StudentData!$O$2:$O$301,StudentData!$N$2:$N$301,">="&4,StudentData!$N$2:$N$301,"<="&7),1),0) -> 12.9
A6: 8-11 | B6: =IFERROR(ROUND(AVERAGEIFS(StudentData!$O$2:$O$301,StudentData!$N$2:$N$301,">="&8,StudentData!$N$2:$N$301,"<="&11),1),0) -> 10.4
A7: 12-15 | B7: =IFERROR(ROUND(AVERAGEIFS(StudentData!$O$2:$O$301,StudentData!$N$2:$N$301,">="&12,StudentData!$N$2:$N$301,"<="&15),1),0) -> 7.7
A8: 16-19 | B8: =IFERROR(ROUND(AVERAGEIFS(StudentData!$O$2:$O$301,StudentData!$N$2:$N$301,">="&16,StudentData!$N$2:$N$301,"<="&19),1),0) -> 6
A9: 20-23 | B9: =IFERROR(ROUND(AVERAGEIFS(StudentData!$O$2:$O$301,StudentData!$N$2:$N$301,">="&20,StudentData!$N$2:$N$301,"<="&23),1),0) -> 9
A10: 24-27 | B10: =IFERROR(ROUND(AVERAGEIFS(StudentData!$O$2:$O$301,StudentData!$N$2:$N$301,">="&24,StudentData!$N$2:$N$301,"<="&27),1),0) -> 0
A11: 28-32 | B11: =IFERROR(ROUND(AVERAGEIFS(StudentData!$O$2:$O$301,StudentData!$N$2:$N$301,">="&28,StudentData!$N$2:$N$301,"<="&32),1),0) -> 0

Sheet Demographics
A1: Demographic Performance by Gender
A3: Gender | B3: Average of Final_Grade | C3: Dropped_Out Rate
A4: F | B4: =ROUND(AVERAGEIFS(StudentData!$O$2:$O$301,StudentData!$B$2:$B$301,A4),1) -> 11.7 | C4: =COUNTIFS(StudentData!$B$2:$B$301,A4,StudentData!$P$2:$P$301,"TRUE")/COUNTIF(StudentData!$B$2:$B$301,A4) -> 0.16770186
A5: M | B5: =ROUND(AVERAGEIFS(StudentData!$O$2:$O$301,StudentData!$B$2:$B$301,A5),1) -> 12.2 | C5: =COUNTIFS(StudentData!$B$2:$B$301,A5,StudentData!$P$2:$P$301,"TRUE")/COUNTIF(StudentData!$B$2:$B$301,A5) -> 0.20863309

Sheet Column Description
A1: Column Descriptions:
A2: 1. School: Name of the school attended (e.g., MS).
A3: 2. Gender: Gender of the student (e.g., M for Male, F for Female).
A4: 3. Age: Age of the student.
A5: 4. Address: Type of residence (U for urban, R for rural).
A6: 7. Mother_Education: Education level of the mother (0 to 4).
A7: 8. Father_Education: Education level of the father (0 to 4).
A8: 9. Mother_Job: Type of job held by the mother.
A9: 10. Father_Job: Type of job held by the father.
A10: 11. Reason_for_Choosing_School: Reason for selecting the school (e.g., course).
A11: 12. Guardian: Guardian of the student (e.g., mother).
A12: 13. Travel_Time: Time taken to travel to school (in minutes).
... A27: 34. Dropped_Out: Indicator of whether the student has dropped out (True/False).
